<?xml version="1.0" ?>
<robot xmlns:xacro="http://www.ros.org/wiki/xacro">
	<xacro:macro name="nimbro_op" params="display_variant collision_variant">
    <material name="black">
      <color rgba="0.1 0.1 0.1 1" />
    </material>

    <material name="white">
      <color rgba="0.8 0.8 0.8 1" />
    </material>

<!-- ======================================================
 Name        : eros.urdf / Eros Robot Model
 Author      : rokhmat@eros
 Version     : 1.0
 Copyright   : EROS <erojaya.bejo> Team
 Description : 
======================================================
 -->

    <link name="trunk_link">
      <inertial>
        <origin xyz="-0.012677 -6.4526E-05 -0.024311" rpy="0 0 0" />
        <mass value="2.045" />
        <inertia ixx="0.00804781" ixy="-0.00001059" ixz="-0.00013634"
        iyy="0.00727409" iyz="-0.00000696" izz="0.00540421" />
      </inertial>
      <visual>
        <origin xyz="0 0 0" rpy="0 0 0" />
        <geometry>
          <!-- <box size="0.12 0.125 0.185" /> -->
          <mesh
          filename="package://nimbro_op_model/mesh/eros/trunk_link.STL" />
        </geometry>
        <material name="white" />
      </visual>
      <collision>
        <origin xyz="0 0 0" rpy="0 0 0" />
        <geometry>
          <!-- <box size="0.12 0.125 0.185" /> -->
          <mesh
          filename="package://nimbro_op_model/mesh/eros/trunk_link.STL" />
        </geometry>
      </collision>
    </link>


    <link name="right_hip_yaw_link">
      <inertial>
        <origin xyz="0.0032766 -0.0013724 -0.0095963" rpy="0 0 0" />
        <mass value="0.025" />
        <inertia ixx="0.00000507" ixy="0.00000000" ixz="0.00000012"
        iyy="0.00001647" iyz="-0.00000021" izz="0.00001529" />
      </inertial>
      <visual>
        <origin xyz="0 0 0" rpy="0 0 0" />
        <geometry>
          <!-- <box size="0.06 0.05 0.03" /> -->
          <mesh
          filename="package://nimbro_op_model/mesh/eros/right_hip_yaw_link.STL" />
        </geometry>
        <material name="black" />
      </visual>
      <collision>
        <origin xyz="0 0 0" rpy="0 0 0" />
        <geometry>
          <!-- <box size="0.06 0.05 0.03" /> -->
          <mesh
          filename="package://nimbro_op_model/mesh/eros/right_hip_yaw_link.STL" />
        </geometry>
      </collision>
    </link>
    <joint name="right_hip_yaw" type="continuous">
      <origin xyz="0 -0.04773 -0.08789" rpy="0 0 0" />
      <parent link="trunk_link" />
      <child link="right_hip_yaw_link" />
      <axis xyz="0 0 1" />
    </joint>


    <link name="right_hip_roll_link">
      <inertial>
        <origin xyz="-0.0191155528309945 -1.96042503744776E-05 -0.0140757799459858" rpy="0 0 0" />
        <mass value="0.31" />
        <inertia ixx="0.00011858" ixy="-0.00000010" ixz="0.00002045"
        iyy="0.00034098" iyz="-0.00000080" izz="0.00029886" />
      </inertial>
      <visual>
        <origin xyz="0 0 0" rpy="0 0 0" />
        <geometry>
          <!-- <box size="0.1 0.05 0.05" /> -->
          <mesh
          filename="package://nimbro_op_model/mesh/eros/right_hip_roll_link.STL" />
        </geometry>
        <material name="white" />
      </visual>
      <collision>
        <origin xyz="0 0 0" rpy="0 0 0" />
        <geometry>
          <!-- <box size="0.1 0.05 0.05" /> -->
          <mesh
          filename="package://nimbro_op_model/mesh/eros/right_hip_roll_link.STL" />
        </geometry>
      </collision>
    </link>
    <joint name="right_hip_roll" type="continuous">
      <origin xyz="4.26083784947351E-05 0 -0.038" rpy="0 0 0" />
      <parent link="right_hip_yaw_link" />
      <child link="right_hip_roll_link" />
      <axis xyz="-1 0 0" />
    </joint>

    <link name="right_thigh_link">
      <inertial>
        <origin xyz="0.0054277 0.00034049 -0.082269" rpy="0 0 0" />
        <mass value="0.19" />
        <inertia ixx="0.00019524" ixy="-0.00000037" ixz="0.00001202"
        iyy="0.00017893" iyz="-0.00000009" izz="0.00008079" />
      </inertial>
      <visual>
        <origin xyz="0 0 0" rpy="0 0 0" />
        <geometry>
          <!-- <box size="0.05 0.05 0.12" /> -->
          <mesh
          filename="package://nimbro_op_model/mesh/eros/right_thigh_link.STL" />
        </geometry>
        <material name="black" />
      </visual>
      <collision>
        <origin xyz="0 0 0" rpy="0 0 0" />
        <geometry>
          <!-- <box size="0.05 0.05 0.12" /> -->
          <mesh
          filename="package://nimbro_op_model/mesh/eros/right_thigh_link.STL" />
        </geometry>
      </collision>
    </link>
    <joint name="right_hip_pitch" type="continuous">
      <origin xyz="0 0.000272865563695893 0" rpy="0 0 0" />
      <parent link="right_hip_roll_link" />
      <child link="right_thigh_link" />
      <axis xyz="0 1 0" />
    </joint>


    <link name="right_shank_link">
      <inertial>
        <origin xyz="0.0084982 1.6653E-16 -0.052577" rpy="0 0 0" />
        <mass value="0.045" />
        <inertia ixx="0.00006993" ixy="0.00000000" ixz="0.00000302"
        iyy="0.00005366" iyz="0.00000000" izz="0.00002875" />
      </inertial>
      <visual>
        <origin xyz="0 0 0" rpy="0 0 0" />
        <geometry>
          <!-- <box size="0.05 0.05 0.12" /> -->
          <mesh
          filename="package://nimbro_op_model/mesh/eros/right_shank_link.STL" />
        </geometry>
        <material name="black" />
      </visual>
      <collision>
        <origin xyz="0 0 0" rpy="0 0 0" />
        <geometry>
          <!-- <box size="0.05 0.05 0.12" /> -->
          <mesh
          filename="package://nimbro_op_model/mesh/eros/right_shank_link.STL" />
        </geometry>
      </collision>
    </link>
    <joint name="right_knee_pitch" type="continuous">
      <origin xyz="0.000139526375362783 0.000754789894666347 -0.110000000000033" rpy="0 0 0" />
      <parent link="right_thigh_link" />
      <child link="right_shank_link" />
      <axis xyz="0 1 0" />
    </joint>


    <link name="right_ankle_link">
      <inertial>
        <origin xyz="-0.019428 -1.1817E-05 0.013886" rpy="0 0 0" />
        <mass value="0.315" />
        <inertia ixx="0.00011956" ixy="-0.00000016" ixz="-0.00002101"
        iyy="0.00035616" iyz="0.00000088" izz="0.00031274" />
      </inertial>
      <visual>
        <origin xyz="0 0 0" rpy="0 0 0" />
        <geometry>
          <!-- <box size="0.09 0.05 0.05" /> -->
          <mesh
          filename="package://nimbro_op_model/mesh/eros/right_ankle_link.STL" />
        </geometry>
        <material name="white" />
      </visual>
      <collision>
        <origin xyz="0 0 0" rpy="0 0 0" />
        <geometry>
          <!-- <box size="0.09 0.05 0.05" /> -->
          <mesh
          filename="package://nimbro_op_model/mesh/eros/right_ankle_link.STL" />
        </geometry>
      </collision>
    </link>
    <joint name="right_ankle_pitch" type="continuous">
      <origin xyz="0 -0.000151355466657691 -0.115" rpy="0 0 0" />
      <parent link="right_shank_link" />
      <child link="right_ankle_link" />
      <axis xyz="0 1 0" />
    </joint>


    <link name="right_foot_link">
      <inertial>
        <origin xyz="0.0032874 -0.0054641 -0.034665" rpy="0 0 0" />
        <mass value="0.08" />
        <inertia ixx="0.00006014" ixy="-0.00000011" ixz="-0.00000006"
        iyy="0.00013602" iyz="0.00000082" izz="0.00018868" />
      </inertial>
      <visual>
        <origin xyz="0 0 0" rpy="0 0 0" />
        <geometry>
          <!-- <box size="0.125 0.08 0.03" /> -->
          <mesh
          filename="package://nimbro_op_model/mesh/eros/right_foot_link.STL" />
        </geometry>
        <material name="black" />
      </visual>
      <collision>
        <origin xyz="0 0 0" rpy="0 0 0" />
        <geometry>
          <!-- <box size="0.125 0.08 0.03" /> -->
          <mesh
          filename="package://nimbro_op_model/mesh/eros/right_foot_link.STL" />
        </geometry>
      </collision>
    </link>
    <joint name="right_ankle_roll" type="continuous">
      <origin xyz="-5.05476446036046E-05 0 0" rpy="0 0 0" />
      <parent link="right_ankle_link" />
      <child link="right_foot_link" />
      <axis xyz="-1 0 0" />
    </joint>


    <link name="right_foot_plane_link">
    </link>
    <joint name="right_foot_plane_joint" type="fixed">
      <origin xyz="${0.1049 - 0.208/2.0} ${-(0.077 - 0.132/2.0)} -0.039"
              rpy="0 0 0" />
      <parent link="right_foot_link" />
      <child link="right_foot_plane_link" />
    </joint>










    <link name="left_hip_yaw_link">
      <inertial>
        <origin xyz="0.0032766 0.0013724 -0.0095963" rpy="0 0 0" />
        <mass value="0.025" />
        <inertia ixx="0.00000507" ixy="0.00000000" ixz="0.00000012"
        iyy="0.00001647" iyz="0.00000021" izz="0.00001529" />
      </inertial>
      <visual>
        <origin xyz="0 0 0" rpy="0 0 0" />
        <geometry>
          <!-- <box size="0.06 0.05 0.03" /> -->
          <mesh
          filename="package://nimbro_op_model/mesh/eros/left_hip_yaw_link.STL" />
        </geometry>
        <material name="black" />
      </visual>
      <collision>
        <origin xyz="0 0 0" rpy="0 0 0" />
        <geometry>
          <!-- <box size="0.06 0.05 0.03" /> -->
          <mesh
          filename="package://nimbro_op_model/mesh/eros/left_hip_yaw_link.STL" />
        </geometry>
      </collision>
    </link>
    <joint name="left_hip_yaw" type="continuous">
      <origin xyz="0 0.04773 -0.08789" rpy="0 0 0" />
      <parent link="trunk_link" />
      <child link="left_hip_yaw_link" />
      <axis xyz="0 0 1" />
    </joint>


<link name="left_hip_roll_link">
      <inertial>
        <origin xyz="-0.019116 2.1864E-05 -0.014076" rpy="0 0 0" />
        <mass value="0.31" />

        <!-- TODO: the origin was shifted by -0.0012 and this was not updated -->
        <inertia ixx="0.00011858" ixy="0.00000013" ixz="0.00002045"
        iyy="0.00034098" iyz="0.00000081" izz="0.00029886" />
      </inertial>
      <visual>
        <origin xyz="0 0 0" rpy="0 0 0" />
        <geometry>
          <!-- <box size="0.1 0.05 0.05" /> -->
          <mesh
          filename="package://nimbro_op_model/mesh/eros/left_hip_roll_link.STL" />
        </geometry>
        <material name="white" />
      </visual>
      <collision>
        <origin xyz="0 0 0" rpy="0 0 0" />
        <geometry>
          <!-- <box size="0.1 0.05 0.05" /> -->
          <mesh
          filename="package://nimbro_op_model/mesh/eros/left_hip_roll_link.STL" />
        </geometry>
      </collision>
    </link>
    <joint name="left_hip_roll" type="continuous">
      <origin xyz="4.26083784947351E-05 0 -0.038" rpy="0 0 0" />
      <parent link="left_hip_yaw_link" />
      <child link="left_hip_roll_link" />
      <axis xyz="-1 0 0" />
    </joint>


    <link name="left_thigh_link">
      <inertial>
        <origin xyz="0.0054277 0.00040708 -0.082269" rpy="0 0 0" />
        <mass value="0.19" />

        <!-- TODO: the origin was shifted by -0.0012 and this was not updated -->
        <inertia ixx="0.00019525" ixy="-0.00000044" ixz="0.00001202"
        iyy="0.00017893" iyz="-0.00000177" izz="0.00008080" />
      </inertial>
      <visual>
        <origin xyz="0 0 0" rpy="0 0 0" />
        <geometry>
          <!-- <box size="0.05 0.05 0.12" /> -->
          <mesh
          filename="package://nimbro_op_model/mesh/eros/left_thigh_link.STL" />
        </geometry>
        <material name="black" />
      </visual>
      <collision>
        <origin xyz="0 0 0" rpy="0 0 0" />
        <geometry>
          <!-- <box size="0.05 0.05 0.12" /> -->
          <mesh
          filename="package://nimbro_op_model/mesh/eros/left_thigh_link.STL" />
        </geometry>
      </collision>
    </link>
    <joint name="left_hip_pitch" type="continuous">
      <origin xyz="0 0.000272865563695893 0" rpy="0 0 0" />
      <parent link="left_hip_roll_link" />
      <child link="left_thigh_link" />
      <axis xyz="0 1 0" />
    </joint>


    <link name="left_shank_link">
      <inertial>
        <origin xyz="0.0075252 1.0577E-05 -0.05034" rpy="0 0 0" />
        <mass value="0.045" />
        <inertia ixx="0.00007047" ixy="0.00000000" ixz="0.00000327"
        iyy="0.00005340" iyz="0.00000000" izz="0.00002925" />
      </inertial>
      <visual>
        <origin xyz="0 0 0" rpy="0 0 0" />
        <geometry>
          <!-- <box size="0.05 0.05 0.12" /> -->
          <mesh
          filename="package://nimbro_op_model/mesh/eros/left_shank_link.STL" />
        </geometry>
        <material name="black" />
      </visual>
      <collision>
        <origin xyz="0 0 0" rpy="0 0 0" />
        <geometry>
          <!-- <box size="0.05 0.05 0.12" /> -->
          <mesh
          filename="package://nimbro_op_model/mesh/eros/left_shank_link.STL" />
        </geometry>
      </collision>
    </link>
    <joint name="left_knee_pitch" type="continuous">
      <origin xyz="0.000139526375362783 0.000754789894666347 -0.110000000000033" rpy="0 0 0" />
      <parent link="left_thigh_link" />
      <child link="left_shank_link" />
      <axis xyz="0 1 0" />
    </joint>


    <link name="left_ankle_link">
      <inertial>
        <origin xyz="-0.019428 3.1732E-05 0.013886" rpy="0 0 0" />
        <mass value="0.315" />
        <inertia ixx="0.00011957" ixy="0.00000011" ixz="-0.00002101"
        iyy="0.00035616" iyz="-0.00000078" izz="0.00031275" />
      </inertial>
      <visual>
        <origin xyz="0 0 0" rpy="0 0 0" />
        <geometry>
          <!-- <box size="0.09 0.05 0.05" /> -->
          <mesh
          filename="package://nimbro_op_model/mesh/eros/left_ankle_link.STL" />
        </geometry>
        <material name="white" />
      </visual>
      <collision>
        <origin xyz="0 0 0" rpy="0 0 0" />
        <geometry>
          <!-- <box size="0.09 0.05 0.05" /> -->
          <mesh
          filename="package://nimbro_op_model/mesh/eros/left_ankle_link.STL" />
        </geometry>
      </collision>
    </link>
    <joint name="left_ankle_pitch" type="continuous">
      <origin xyz="0 -0.000151355466657691 -0.115" rpy="0 0 0" />
      <parent link="left_shank_link" />
      <child link="left_ankle_link" />
      <axis xyz="0 1 0" />
    </joint>


    <link name="left_foot_link">
      <inertial>
        <origin xyz="0.0032875 0.005474 -0.034679" rpy="0 0 0" />
        <mass value="0.08" />
        <inertia ixx="0.00006025" ixy="0.00000011" ixz="-0.00000006"
        iyy="0.00013700" iyz="-0.00000082" izz="0.00018981" />
      </inertial>
      <visual>
        <origin xyz="0 0 0" rpy="0 0 0" />
        <geometry>
          <!-- <box size="0.125 0.08 0.03" /> -->
          <mesh
          filename="package://nimbro_op_model/mesh/eros/left_foot_link.STL" />
        </geometry>
        <material name="black" />
      </visual>
      <collision>
        <origin xyz="0 0 0" rpy="0 0 0" />
        <geometry>
          <!-- <box size="0.125 0.08 0.03" / -->
          <mesh
          filename="package://nimbro_op_model/mesh/eros/left_foot_link.STL" />
        </geometry>
      </collision>
    </link>
    <joint name="left_ankle_roll" type="continuous">
      <origin xyz="-5.05476446036046E-05 0 0
        " rpy="0 0 0" />
      <parent link="left_ankle_link" />
      <child link="left_foot_link" />
      <axis xyz="-1 0 0" />
    </joint>


    <link name="left_foot_plane_link">
    </link>
    <joint name="left_foot_plane_joint" type="fixed">
      <origin xyz="${0.1049 - 0.208/2.0} ${0.077 - 0.132/2.0} -0.039"
              rpy="0 0 0" />
      <parent link="left_foot_link" />
      <child link="left_foot_plane_link" />
    </joint>










    <link name="right_shoulder_pitch_link">
      <inertial>
        <origin xyz="-1.3878E-17 -0.0076523 -0.0013887" rpy="0 0 0" />
        <mass value="0.015" />
        <inertia ixx="0.00000210" ixy="0.00000000" ixz="0.00000000"
        iyy="0.00000601" iyz="0.00000048" izz="0.00000587" />
      </inertial>
      <visual>
        <origin xyz="0 0 0" rpy="0 0 0" />
        <geometry>
          <!-- <box size="0.05 0.04 0.03" /> -->
          <mesh
          filename="package://nimbro_op_model/mesh/eros/right_shoulder_pitch_link.STL" />
        </geometry>
        <material name="black" />
      </visual>
      <collision>
        <origin xyz="0 0 0" rpy="0 0 0" />
        <geometry>
          <!-- <box size="0.05 0.04 0.03" /> -->
          <mesh
          filename="package://nimbro_op_model/mesh/eros/right_shoulder_pitch_link.STL" />
        </geometry>
      </collision>
    </link>
    <joint name="right_shoulder_pitch" type="continuous">
      <origin xyz="0 -0.0656181565488089 0.0548"
      rpy="0 0 0" />
      <parent link="trunk_link" />
      <child link="right_shoulder_pitch_link" />
      <axis xyz="0 1 0" />
    </joint>


    <link name="right_upper_arm_link">
      <inertial>
        <origin xyz="0.0041194 -2.878E-05 -0.052043" rpy="0 0 0" />
        <mass value="0.19" />
        <inertia ixx="3.10603262" ixy="-0.00443730" ixz="-0.31507611"
        iyy="3.21396085" iyz="0.00226046" izz="0.49438947" />
      </inertial>
      <visual>
        <origin xyz="0 0 0" rpy="0 0 0" />
        <geometry>
          <!-- <box size="0.04 0.05 0.15" /> -->
          <mesh
          filename="package://nimbro_op_model/mesh/eros/right_upper_arm_link.STL" />
        </geometry>
        <material name="black" />
      </visual>
      <collision>
        <origin xyz="0 0 0" rpy="0 0 0" />
        <geometry>
          <!-- <box size="0.04 0.05 0.15" /> -->
          <mesh
          filename="package://nimbro_op_model/mesh/eros/right_upper_arm_link.STL" />
        </geometry>
      </collision>
    </link>
    <joint name="right_shoulder_roll" type="continuous">
      <origin xyz="-0.00027665735414488 -0.0240000000000005 -0.0159973139955498"
      rpy="0 0 0" />
      <parent link="right_shoulder_pitch_link" />
      <child link="right_upper_arm_link" />
      <axis xyz="1 0 0" />
    </joint>


    <link name="right_lower_arm_link">
      <inertial>
        <origin xyz="-0.015624 -0.011146 -0.060255" rpy="0 0 0" />
        <mass value="0.065" />
        <inertia ixx="0.00014580" ixy="0.00000027" ixz="0.00000162"
        iyy="0.00014322" iyz="0.00002040" izz="0.00002313" />
      </inertial>
      <visual>
        <origin xyz="0 0 0" rpy="0 0 0" />
        <geometry>
          <!-- <box size="0.042 0.047 0.13" /> -->
          <mesh
          filename="package://nimbro_op_model/mesh/eros/right_lower_arm_link.STL" />
        </geometry>
        <material name="black" />
      </visual>
      <collision>
        <origin xyz="0 0 0" rpy="0 0 0" />
        <geometry>
          <!-- <box size="0.042 0.047 0.13" /> -->
          <mesh
          filename="package://nimbro_op_model/mesh/eros/right_lower_arm_link.STL" />
        </geometry>
      </collision>
    </link>
    <joint name="right_elbow_pitch" type="continuous">
      <origin xyz="0.0210000000000005 -5.04771949249166E-05 -0.0934000000000005"
      rpy="0 0 0" />
      <parent link="right_upper_arm_link" />
      <child link="right_lower_arm_link" />
      <axis xyz="0 -1 0" />
    </joint>









    <link name="left_shoulder_pitch_link">
      <inertial>
        <origin xyz="1.3878E-17 0.0076523 -0.0013887" rpy="0 0 0" />
        <mass value="0.015" />
        <inertia ixx="0.00000210" ixy="0.00000000" ixz="0.00000000"
        iyy="0.00000601" iyz="-0.00000048" izz="0.00000587" />
      </inertial>
      <visual>
        <origin xyz="0 0 0" rpy="0 0 0" />
        <geometry>
          <!-- <box size="0.05 0.04 0.03" /> -->
          <mesh
          filename="package://nimbro_op_model/mesh/eros/left_shoulder_pitch_link.STL" />
        </geometry>
        <material name="black" />
      </visual>
      <collision>
        <origin xyz="0 0 0" rpy="0 0 0" />
        <geometry>
          <!-- <box size="0.05 0.04 0.03" /> -->
          <mesh
          filename="package://nimbro_op_model/mesh/eros/left_shoulder_pitch_link.STL" />
        </geometry>
      </collision>
    </link>
    <joint name="left_shoulder_pitch" type="continuous">
      <origin xyz="0 0.0656181565488089 0.0548"
      rpy="0 0 0" />
      <parent link="trunk_link" />
      <child link="left_shoulder_pitch_link" />
      <axis xyz="0 1 0" />
    </joint>



    <link name="left_upper_arm_link">
      <inertial>
        <origin xyz="0.0041194 2.878E-05 -0.052043" rpy="0 0 0" />
        <mass value="0.19" />
        <inertia ixx="0.00031060" ixy="0.00000044" ixz="-0.00003151"
        iyy="0.00032140" iyz="-0.00000023" izz="0.00004944" />
      </inertial>
      <visual>
        <origin xyz="0 0 0" rpy="0 0 0" />
        <geometry>
          <!-- <box size="0.04 0.05 0.15" /> -->
          <mesh
          filename="package://nimbro_op_model/mesh/eros/left_upper_arm_link.STL" />
        </geometry>
        <material name="black" />
      </visual>
      <collision>
        <origin xyz="0 0 0" rpy="0 0 0" />
        <geometry>
          <!-- <box size="0.04 0.05 0.15" /> -->
          <mesh
          filename="package://nimbro_op_model/mesh/eros/left_upper_arm_link.STL" />
        </geometry>
      </collision>
    </link>
    <joint name="left_shoulder_roll" type="continuous">
      <origin xyz="-0.00027665735414488 0.0240000000000005 -0.0159973139955498"
      rpy="0 0 0" />
      <parent link="left_shoulder_pitch_link" />
      <child link="left_upper_arm_link" />
      <axis xyz="1 0 0" />
    </joint>



    <link name="left_lower_arm_link">
      <inertial>
        <origin xyz="-0.015624 0.011146 -0.060255" rpy="0 0 0" />
        <mass value="0.065" />
        <inertia ixx="0.00014580" ixy="-0.00000027" ixz="0.00000162"
        iyy="0.00014322" iyz="-0.00002040" izz="0.00002313" />
      </inertial>
      <visual>
        <origin xyz="0 0 0" rpy="0 0 0" />
        <geometry>
          <!-- <box size="0.042 0.047 0.13" /> -->
          <mesh
          filename="package://nimbro_op_model/mesh/eros/left_lower_arm_link.STL" />
        </geometry>
        <material name="black" />
      </visual>
      <collision>
        <origin xyz="0 0 0" rpy="0 0 0" />
        <geometry>
          <!-- <box size="0.042 0.047 0.13" /> -->
          <mesh
          filename="package://nimbro_op_model/mesh/eros/left_lower_arm_link.STL" />
        </geometry>
      </collision>
    </link>
    <joint name="left_elbow_pitch" type="continuous">
      <origin xyz="0.0210000000000005 -5.04771949249166E-05 -0.0934000000000005"
      rpy="0 0 0" />
      <parent link="left_upper_arm_link" />
      <child link="left_lower_arm_link" />
      <axis xyz="0 -1 0" />
    </joint>










    <link name="neck_link">
      <inertial>
        <origin xyz="-0.0062349 6.0281E-05 0.019685" rpy="0 0 0" />
        <mass value="0.095" />
        <inertia ixx="0.00002088" ixy="0.00000043" ixz="-0.00000149"
        iyy="0.00002516" iyz="0.00000001" izz="0.00002717" />
      </inertial>
      <visual>
        <origin xyz="0 0 0" rpy="0 0 0" />
        <geometry>
          <!-- <box size="0.04 0.04 0.09" /> -->
          <mesh
          filename="package://nimbro_op_model/mesh/eros/neck_link.STL" />
        </geometry>
        <material name="black" />
      </visual>
      <collision>
        <origin xyz="0 0 0" rpy="0 0 0" />
        <geometry>
          <!-- <box size="0.04 0.04 0.09" /> -->
          <mesh
          filename="package://nimbro_op_model/mesh/eros/neck_link.STL" />
        </geometry>
      </collision>
    </link>
    <joint name="neck_yaw" type="continuous">
      <origin xyz="0 0 0.077862"
      rpy="0 0 0" />
      <parent link="trunk_link" />
      <child link="neck_link" />
      <axis xyz="0 0 1" />
    </joint>


    <link name="head_link">
      <inertial>
        <origin xyz="-0.015 -5.0778E-06 0.049483" rpy="0 0 0" />
        <mass value="0.11" />
        <inertia ixx="0.00014399" ixy="0.00000000" ixz="-0.00000060"
        iyy="0.00009214" iyz="0.00000001" izz="0.00013728" />
      </inertial>
      <visual>
        <origin xyz="0 0 0" rpy="0 0 0" />
        <geometry>
          <!-- <box size="0.09 0.07 0.09" /> -->
          <mesh
          filename="package://nimbro_op_model/mesh/eros/head_link.STL" />
        </geometry>
        <material name="white"/>
      </visual>
      <collision>
        <origin xyz="0 0 0" rpy="0 0 0" />
        <geometry>
          <!-- <box size="0.09 0.07 0.09" /> -->
          <mesh
          filename="package://nimbro_op_model/mesh/eros/head_link.STL" />
        </geometry>
      </collision>
    </link>   
    <joint name="head_pitch" type="continuous">
      <origin xyz="0.00400000000000034 0.000266141079259985 0.0222"
      rpy="0 0 0" />
      <parent link="neck_link" />
      <child link="head_link" />
      <axis xyz="0 1 0" />
    </joint>


    
    <link name="camera_optical">
      <inertial>
        <origin xyz="-9.8681E-10 0.00068557 -0.025066" rpy="0 0 0" />
        <mass value="0.095" />
        <inertia ixx="0.00002615" ixy="0.00000000" ixz="0.00000000"
        iyy="0.00002587" iyz="-0.00000062" izz="0.00000888" />
      </inertial>
      <visual>
        <origin xyz="0 0 0" rpy="0 0 0" />
        <geometry>
          <!-- <box size="0.09 0.07 0.09" /> -->
          <mesh
          filename="package://nimbro_op_model/mesh/eros/camera_optical.STL" />
        </geometry>
        <material name="black"/>
      </visual>
      <collision>
        <origin xyz="0 0 0" rpy="0 0 0" />
        <geometry>
          <!-- <box size="0.09 0.07 0.09" /> -->
          <mesh
          filename="package://nimbro_op_model/mesh/eros/camera_optical.STL" />
        </geometry>
      </collision>
    </link>
    <joint name="camera_joint" type="fixed">
      <origin xyz="0.012 0 0.045383"
      rpy="-1.57079632679489 0 -1.57079632679489" />
      <parent link="head_link" />
      <child link="camera_optical" />
      <axis xyz="0 0 0" />
    </joint>









		<!-- Transmissions -->
		<transmission name="right_hip_yaw_transmission">
			<type>transmission_interface/SimpleTransmission</type>
			<joint name="right_hip_yaw" >
                <hardwareInterface>EffortJointInterface</hardwareInterface>
            </joint>
			<actuator name="right_hip_yaw">
				<mechanicalReduction>1</mechanicalReduction>
			</actuator>
		</transmission>
		<transmission name="right_hip_roll_transmission">
			<type>transmission_interface/SimpleTransmission</type>
            <joint name="right_hip_roll" >
				<hardwareInterface>EffortJointInterface</hardwareInterface>
            </joint>
			<actuator name="right_hip_roll">
				<mechanicalReduction>1</mechanicalReduction>
			</actuator>
		</transmission>
		<transmission name="right_hip_pitch_transmission">
			<type>transmission_interface/SimpleTransmission</type>
            <joint name="right_hip_pitch" >
				<hardwareInterface>EffortJointInterface</hardwareInterface>
            </joint>
			<actuator name="right_hip_pitch">
				<mechanicalReduction>1</mechanicalReduction>
			</actuator>
		</transmission>
		<transmission name="right_knee_pitch_transmission">
			<type>transmission_interface/SimpleTransmission</type>
            <joint name="right_knee_pitch" >
				<hardwareInterface>EffortJointInterface</hardwareInterface>
            </joint>
			<actuator name="right_knee_pitch">
				<mechanicalReduction>1</mechanicalReduction>
			</actuator>
		</transmission>
		<transmission name="right_ankle_pitch_transmission">
			<type>transmission_interface/SimpleTransmission</type>
            <joint name="right_ankle_pitch" >
				<hardwareInterface>EffortJointInterface</hardwareInterface>
            </joint>
			<actuator name="right_ankle_pitch">
				<mechanicalReduction>1</mechanicalReduction>
			</actuator>
		</transmission>
		<transmission name="right_ankle_roll_transmission">
			<type>transmission_interface/SimpleTransmission</type>
            <joint name="right_ankle_roll" >
                <hardwareInterface>EffortJointInterface</hardwareInterface>
            </joint>
			<actuator name="right_ankle_roll">
				<mechanicalReduction>1</mechanicalReduction>
			</actuator>
		</transmission>
		<transmission name="left_hip_yaw_transmission">
			<type>transmission_interface/SimpleTransmission</type>
            <joint name="left_hip_yaw" >
				<hardwareInterface>EffortJointInterface</hardwareInterface>
            </joint>
			<actuator name="left_hip_yaw">
				<mechanicalReduction>1</mechanicalReduction>
			</actuator>
		</transmission>
		<transmission name="left_hip_roll_transmission">
			<type>transmission_interface/SimpleTransmission</type>
            <joint name="left_hip_roll" >
				<hardwareInterface>EffortJointInterface</hardwareInterface>
            </joint>
			<actuator name="left_hip_roll">
				<mechanicalReduction>1</mechanicalReduction>
			</actuator>
		</transmission>
		<transmission name="left_hip_pitch_transmission">
			<type>transmission_interface/SimpleTransmission</type>
            <joint name="left_hip_pitch" >
				<hardwareInterface>EffortJointInterface</hardwareInterface>
            </joint>
			<actuator name="left_hip_pitch">
				<mechanicalReduction>1</mechanicalReduction>
			</actuator>
		</transmission>
		<transmission name="left_knee_pitch_transmission">
			<type>transmission_interface/SimpleTransmission</type>
            <joint name="left_knee_pitch" >
				<hardwareInterface>EffortJointInterface</hardwareInterface>
            </joint>
			<actuator name="left_knee_pitch">
				<mechanicalReduction>1</mechanicalReduction>
			</actuator>
		</transmission>
		<transmission name="left_ankle_pitch_transmission">
			<type>transmission_interface/SimpleTransmission</type>
            <joint name="left_ankle_pitch" >
				<hardwareInterface>EffortJointInterface</hardwareInterface>
            </joint>
			<actuator name="left_ankle_pitch">
				<mechanicalReduction>1</mechanicalReduction>
			</actuator>
		</transmission>
		<transmission name="left_ankle_roll_transmission">
			<type>transmission_interface/SimpleTransmission</type>
            <joint name="left_ankle_roll" >
				<hardwareInterface>EffortJointInterface</hardwareInterface>
            </joint>
			<actuator name="left_ankle_roll">
				<mechanicalReduction>1</mechanicalReduction>
			</actuator>
		</transmission>
		<transmission name="right_shoulder_pitch_transmission">
			<type>transmission_interface/SimpleTransmission</type>
            <joint name="right_shoulder_pitch" >
				<hardwareInterface>EffortJointInterface</hardwareInterface>
            </joint>
			<actuator name="right_shoulder_pitch">
				<mechanicalReduction>1</mechanicalReduction>
			</actuator>
		</transmission>
		<transmission name="right_shoulder_roll_transmission">
			<type>transmission_interface/SimpleTransmission</type>
            <joint name="right_shoulder_roll" >
				<hardwareInterface>EffortJointInterface</hardwareInterface>
            </joint>
			<actuator name="right_shoulder_roll">
				<mechanicalReduction>1</mechanicalReduction>
			</actuator>
		</transmission>
		<transmission name="right_elbow_pitch_transmission">
			<type>transmission_interface/SimpleTransmission</type>
            <joint name="right_elbow_pitch" >
				<hardwareInterface>EffortJointInterface</hardwareInterface>
            </joint>
			<actuator name="right_elbow_pitch">
				<mechanicalReduction>1</mechanicalReduction>
			</actuator>
		</transmission>
		<transmission name="left_shoulder_pitch_transmission">
			<type>transmission_interface/SimpleTransmission</type>
            <joint name="left_shoulder_pitch" >
				<hardwareInterface>EffortJointInterface</hardwareInterface>
            </joint>
			<actuator name="left_shoulder_pitch">
				<mechanicalReduction>1</mechanicalReduction>
			</actuator>
		</transmission>
		<transmission name="left_shoulder_roll_transmission">
			<type>transmission_interface/SimpleTransmission</type>
            <joint name="left_shoulder_roll" >
				<hardwareInterface>EffortJointInterface</hardwareInterface>
            </joint>
			<actuator name="left_shoulder_roll">
				<mechanicalReduction>1</mechanicalReduction>
			</actuator>
		</transmission>
		<transmission name="left_elbow_pitch_transmission">
			<type>transmission_interface/SimpleTransmission</type>
            <joint name="left_elbow_pitch" >
				<hardwareInterface>EffortJointInterface</hardwareInterface>
            </joint>
			<actuator name="left_elbow_pitch">
				<mechanicalReduction>1</mechanicalReduction>
			</actuator>
		</transmission>
		<transmission name="neck_yaw_transmission">
			<type>transmission_interface/SimpleTransmission</type>
            <joint name="neck_yaw" >
				<hardwareInterface>EffortJointInterface</hardwareInterface>
            </joint>
			<actuator name="neck_yaw">
				<mechanicalReduction>1</mechanicalReduction>
			</actuator>
		</transmission>
		<transmission name="head_pitch_transmission">
			<type>transmission_interface/SimpleTransmission</type>
            <joint name="head_pitch" >
				<hardwareInterface>EffortJointInterface</hardwareInterface>
            </joint>
			<actuator name="head_pitch">
				<mechanicalReduction>1</mechanicalReduction>
			</actuator>
		</transmission>


		<!-- Gazebo configuration -->

		<gazebo>
			<plugin name="gazebo_ros_control" filename="libgazebo_ros_control.so">
				<robotNamespace>/nimbro_op</robotNamespace>
			</plugin>
		</gazebo>

		<!-- Gazebo links -->
		<gazebo reference="trunk_link">
			<material>Gazebo/FlatBlack</material>
		</gazebo>
		<gazebo reference="left_hip_yaw_link">
			<material>Gazebo/FlatBlack</material>
		</gazebo>
		<gazebo reference="left_hip_roll_link">
			<material>Gazebo/Black</material>
		</gazebo>
		<gazebo reference="left_thigh_link">
			<material>Gazebo/FlatBlack</material>
		</gazebo>
		<gazebo reference="left_shank_link">
			<material>Gazebo/FlatBlack</material>
		</gazebo>
		<gazebo reference="left_ankle_link">
			<material>Gazebo/Black</material>
		</gazebo>
		<gazebo reference="left_foot_link">
			<material>Gazebo/FlatBlack</material>
			<kp>1000000.0</kp>
			<kd>100.0</kd>
			<mu1>1.0</mu1>
			<mu2>1.0</mu2>
			<fdir1>1 0 0</fdir1>
			<maxVel>1.0</maxVel>
			<minDepth>0.00</minDepth>
		</gazebo>
		<gazebo reference="left_shoulder_pitch_link">
			<material>Gazebo/Black</material>
		</gazebo>
		<gazebo reference="left_upper_arm_link">
			<material>Gazebo/FlatBlack</material>
		</gazebo>
		<gazebo reference="left_lower_arm_link">
			<material>Gazebo/FlatBlack</material>
		</gazebo>
		<gazebo reference="right_hip_yaw_link">
			<material>Gazebo/FlatBlack</material>
		</gazebo>
		<gazebo reference="right_hip_roll_link">
			<material>Gazebo/Black</material>
		</gazebo>
		<gazebo reference="right_thigh_link">
			<material>Gazebo/FlatBlack</material>
		</gazebo>
		<gazebo reference="right_shank_link">
			<material>Gazebo/FlatBlack</material>
		</gazebo>
		<gazebo reference="right_ankle_link">
			<material>Gazebo/Black</material>
		</gazebo>
		<gazebo reference="right_foot_link">
			<material>Gazebo/FlatBlack</material>
			<kp>1000000.0</kp>
			<kd>100.0</kd>
			<mu1>1.0</mu1>
			<mu2>1.0</mu2>
			<fdir1>1 0 0</fdir1>
			<maxVel>1.0</maxVel>
			<minDepth>0.00</minDepth>
		</gazebo>
		<gazebo reference="right_shoulder_pitch_link">
			<material>Gazebo/Black</material>
		</gazebo>
		<gazebo reference="right_upper_arm_link">
			<material>Gazebo/FlatBlack</material>
		</gazebo>
		<gazebo reference="right_lower_arm_link">
			<material>Gazebo/FlatBlack</material>
		</gazebo>
		<gazebo reference="neck_link">
			<material>Gazebo/Black</material>
		</gazebo>
	</xacro:macro>
</robot>
